<?xml version="1.0" ?>
<robot name="jsc_mobile_bot" xmlns:xacro="http://ros.org/wiki/xacro">
  <!-- Definición de los parámetros del robot -->
  <xacro:property name="base_width" value="0.17"/>
  <xacro:property name="base_length" value="0.19"/>
  <xacro:property name="base_height" value="0.18"/>

  <!-- Define la forma de las ruedas -->
  <xacro:property name="wheel_radius" value="0.04"/>
  <xacro:property name="wheel_width" value="0.035"/>

  <xacro:property name="wheel_ygap" value="0.015"/>
  <xacro:property name="wheel_zoff" value="0.075"/>
  <xacro:property name="wheel_xoff" value="0.095"/>

  <!-- Macros de inercia -->
  <xacro:macro name="box_inertia" params="m w h d">
    <inertial>
      <origin xyz="0 0 0" rpy="${pi/2} 0 ${pi/2}"/>
      <mass value="${m}"/>
      <inertia ixx="${(m/12) * (h*h + d*d)}" ixy="0.0" ixz="0.0" iyy="${(m/12) * (w*w + d*d)}" iyz="0.0" izz="${(m/12) * (w*w + h*h)}"/>
    </inertial>
  </xacro:macro>

  <xacro:macro name="cylinder_inertia" params="m r h">
    <inertial>
      <origin xyz="0 0 0" rpy="${pi/2} 0 0" />
      <mass value="${m}"/>
      <inertia ixx="${(m/12) * (3*r*r + h*h)}" ixy = "0" ixz = "0" iyy="${(m/12) * (3*r*r + h*h)}" iyz = "0" izz="${(m/2) * (r*r)}"/>
    </inertial>
  </xacro:macro>

  <!-- ****************** ROBOT BASE FOOTPRINT ***************************  -->
  <link name="base_footprint"/>
  <joint name="base_joint" type="fixed">
    <origin xyz="0 0 0"/>
    <parent link="base_footprint"/>
    <child link="base_link" />
    <origin xyz="0.0 0.0 ${(wheel_radius+wheel_zoff)}" rpy="0 0 0"/>
  </joint>

  <link name="base_link">
    <visual>
      <origin xyz="0 0 0.02" rpy="1.5707963267949 0 3.141592654"/>
      <geometry>
        <box size="${base_length} ${base_width} ${base_height}"/> 
      </geometry>
      <material name="Red">
        <color rgba="${255/255} ${0/255} ${0/255} 1.0"/>
      </material>
    </visual>
    <collision>
      <geometry>
        <box size="${base_length} ${base_width} ${base_height}"/>
      </geometry>
    </collision>

    <inertial>
      <origin xyz="0 0 0.02"/>
      <mass value="2.5"/>
      <inertia ixx="0.0001873" ixy="0" ixz="0" iyy="0.000055" iyz="0" izz="0.0002283"/>
    </inertial>
  </link>

  <gazebo reference="base_link">
    <material>Gazebo/Red</material>
  </gazebo>

  <!-- *********************** DRIVE WHEELS ******************************  -->
  <xacro:macro name="wheel" params="prefix x_reflect y_reflect">
    <link name="${prefix}_link">
      <visual>
        <origin xyz="0 0 0" rpy="1.5707963267949 0 0"/>
        <geometry>
          <cylinder radius="${wheel_radius}" length="${wheel_width}"/>
        </geometry>
        <material name="White">
          <color rgba="${255/255} ${255/255} ${255/255} 1.0"/>
        </material>
      </visual>
      <collision>
        <origin xyz="0 0 0" rpy="${pi/2} 0 0"/>
        <geometry>
          <cylinder radius="${wheel_radius}" length="${wheel_width}"/>
        </geometry>
      </collision>
      <xacro:cylinder_inertia m="0.15" r="${wheel_radius}" h="${wheel_width}"/>  <!-- Ajusta la masa de las ruedas -->
    </link>
    <transmission name="${prefix}_trans">
      <type>transmission_interface/SimpleTransmission</type>
      <joint name="${prefix}_joint" type="revolute">
        <parent link="base_link"/>
        <child link="${prefix}_link"/>
        <origin xyz="${x_reflect*wheel_xoff} ${y_reflect*(base_width/2+wheel_ygap)} ${-wheel_zoff}" rpy="0 0 0"/>
        <limit upper="3.1415" lower="-3.1415" effort="30" velocity="5.0"/>
        <axis xyz="0 1 0"/>
        <hardwareInterface>hardware_interface/VelocityJointInterface</hardwareInterface>
      </joint>
      <actuator name="${prefix}_motor">
        <hardwareInterface>hardware_interface/VelocityJointInterface</hardwareInterface>
        <mechanicalReduction>1</mechanicalReduction>
      </actuator>
    </transmission>
    <joint name="${prefix}_joint" type="revolute">
      <parent link="base_link"/>
      <child link="${prefix}_link"/>
      <origin xyz="${x_reflect*wheel_xoff} ${y_reflect*(base_width/2+wheel_ygap)} ${-wheel_zoff}" rpy="0 0 0"/>
      <limit upper="3.1415" lower="-3.1415" effort="30" velocity="5.0"/>
      <axis xyz="0 1 0"/>
    </joint>
  </xacro:macro>

  <!-- Instanciación de las cuatro ruedas -->
  <xacro:wheel prefix="drivewhl_fl" x_reflect="1" y_reflect="1" />
  <xacro:wheel prefix="drivewhl_fr" x_reflect="1" y_reflect="-1" />
  <xacro:wheel prefix="drivewhl_bl" x_reflect="-1" y_reflect="1" />
  <xacro:wheel prefix="drivewhl_br" x_reflect="-1" y_reflect="-1" />

  <!-- *********************** IMU SETUP *********************************  -->
  <joint name="imu_joint" type="fixed">
    <parent link="base_link"/>
    <child link="imu_link"/>
    <origin xyz="-0.05 0 0.01" rpy="0 0 0"/>
  </joint>
  <link name="imu_link"/>

  <!-- *********************** GPS SETUP **********************************  -->
  <joint name="gps_joint" type="fixed">
    <parent link="base_link"/>
    <child link="gps_link"/>
    <origin xyz="0.05 0 0.01" rpy="0 0 0"/>
  </joint>
  <link name="gps_link"/>

  <!-- *********************** LIDAR SETUP **********************************  -->
  <joint name="lidar_joint" type="fixed">
    <parent link="base_link"/>
    <child link="lidar_link"/>
    <origin xyz="0.05 0 0.05" rpy="0 0 0"/>
  </joint>

  <link name="lidar_link">
    <collision>
     <origin xyz="0 0 0" rpy="0 0 0"/>
     <geometry>
      <cylinder radius="0.0508" length="0.02"/>
     </geometry>
    </collision>
    
    <visual>
     <origin xyz="0 0 0" rpy="0 0 0"/>
     <geometry>
      <cylinder radius="0.0508" length="0.02"/>
     </geometry>
     <material name="Black">
          <color rgba="${0/255} ${0/255} ${0/255} 1.0"/>
     </material>
    </visual>
    
    <inertial>
      <mass value="0.114" />
      <origin xyz="0 0 0" rpy="0 0 0"/>
      <inertia ixx="0.001" ixy="0" ixz="0" iyy="0.001" iyz="0" izz="0.001" />
    </inertial>
  </link>





  <!-- *********************** ROS2_CONTROL ***************************    -->

<ros2_control name="GazeboSystem" type="system">
  <hardware>
    <plugin>gazebo_ros2_control/GazeboSystem</plugin>
  </hardware>
  <joint name="drivewhl_fl_joint">
    <command_interface name="velocity">
      <param name="min">-3.14</param>
      <param name="max">3.14</param>
    </command_interface>
    <state_interface name="position">
      <param name="initial_value">0</param>
    </state_interface>
    <state_interface name="velocity"/>
    <state_interface name="effort"/>
  </joint>

  <joint name="drivewhl_fr_joint">
    <command_interface name="velocity">
      <param name="min">-3.14</param>
      <param name="max">3.14</param>
    </command_interface>
    <state_interface name="position">
      <param name="initial_value">0</param>
    </state_interface>
    <state_interface name="velocity"/>
    <state_interface name="effort"/>
  </joint>
  <joint name="drivewhl_bl_joint">
    <command_interface name="velocity">
      <param name="min">-3.14</param>
      <param name="max">3.14</param>
    </command_interface>
    <state_interface name="position">
      <param name="initial_value">0</param>
    </state_interface>
    <state_interface name="velocity"/>
    <state_interface name="effort"/>
  </joint>

  <joint name="drivewhl_br_joint">
    <command_interface name="velocity">
      <param name="min">-3.14</param>
      <param name="max">3.14</param>
    </command_interface>
    <state_interface name="position">
      <param name="initial_value">0</param>
    </state_interface>
    <state_interface name="velocity"/>
    <state_interface name="effort"/>
  </joint>
</ros2_control>

<plugin name="gazebo_ros2_control" filename="libgazebo_ros2_control.so">
  <parameters>/home/jsc/ros2_ws/install/jsc_mobile_robot/share/jsc_mobile_robot/config/my_controllers.yaml</parameters>
</plugin>


</robot>
